<?xml version="1.0"?>
<sdf version="1.9">
    <world name="car_world">
        <physics name="1ms" type="ignored">
            <max_step_size>0.001</max_step_size>
            <real_time_factor>1.0</real_time_factor>
        </physics>
        <plugin
            filename="gz-sim-physics-system"
            name="gz::sim::systems::Physics">
        </plugin>
        <plugin
            filename="gz-sim-user-commands-system"
            name="gz::sim::systems::UserCommands">
        </plugin>
        <plugin
            filename="gz-sim-scene-broadcaster-system"
            name="gz::sim::systems::SceneBroadcaster">
        </plugin>

        <plugin
            filename="ignition-gazebo-imu-system"
            name="ignition::gazebo::systems::Imu">
        </plugin>
        <plugin
            filename="ignition-gazebo-navsat-system"
            name="ignition::gazebo::systems::NavSat">
        </plugin>

        <spherical_coordinates>
            <surface_model>EARTH_WGS84</surface_model>
            <world_frame_orientation>ENU</world_frame_orientation>
            <latitude_deg>-22.9</latitude_deg>
            <longitude_deg>-43.2</longitude_deg>
            <elevation>0</elevation>
            <heading_deg>0</heading_deg>
        </spherical_coordinates>


        <light type="directional" name="sun">
            <cast_shadows>true</cast_shadows>
            <pose>0 0 10 0 0 0</pose>
            <diffuse>0.8 0.8 0.8 1</diffuse>
            <specular>0.2 0.2 0.2 1</specular>
            <attenuation>
                <range>1000</range>
                <constant>0.9</constant>
                <linear>0.01</linear>
                <quadratic>0.001</quadratic>
            </attenuation>
            <direction>-0.5 0.1 -0.9</direction>
        </light>

        <model name="ground_plane">
            <static>true</static>
            <link name="link">
                <collision name="collision">
                    <geometry>
                        <plane>
                            <normal>0 0 1</normal>
                        </plane>
                    </geometry>
                </collision>
                <visual name="visual">
                    <geometry>
                        <plane>
                            <normal>0 0 1</normal>
                            <size>100 100</size>
                        </plane>
                    </geometry>
                    <material>
                        <ambient>0.8 0.8 0.8 1</ambient>
                        <diffuse>0.8 0.8 0.8 1</diffuse>
                        <specular>0.8 0.8 0.8 1</specular>
                    </material>
                </visual>
            </link>
        </model>


        <model name='mobile_robot' canonical_link='chassis'>

            <plugin
                filename="gz-sim-diff-drive-system"
                name="gz::sim::systems::DiffDrive">
                <left_joint>left_wheel_joint</left_joint>
                <right_joint>right_wheel_joint</right_joint>
                <wheel_separation>1.2</wheel_separation>
                <wheel_radius>0.4</wheel_radius>
                <odom_publish_frequency>1</odom_publish_frequency>
                <topic>cmd_vel</topic>
            </plugin>

            <frame name="caster_frame" attached_to='chassis'>
                <pose>0.8 0 -0.2 0 0 0</pose>
            </frame>

            <pose relative_to='world'>0 0 0 0 0 0</pose>

            <!-- Chassis -->
            <link name='chassis'>
                <sensor name="imu_sensor" type="imu">
                    <always_on>true</always_on>
                    <update_rate>200</update_rate>
                    <visualize>false</visualize>
                    <pose>0 0 0.05 0 0 0</pose>
                    <topic>imu</topic>
                    <imu>
                        <angular_velocity>
                            <x>
                                <noise type="gaussian">
                                    <mean>0.0</mean>
                                    <stddev>0.002</stddev>          <!-- rad/s white noise -->
                                    <bias_mean>0.0005</bias_mean>   <!-- rad/s bias -->
                                    <bias_stddev>1e-4</bias_stddev> <!-- rad/s bias RW -->
                                </noise>
                            </x>
                            <y>
                                <noise type="gaussian">
                                    <mean>0.0</mean>
                                    <stddev>0.002</stddev>
                                    <bias_mean>0.0005</bias_mean>
                                    <bias_stddev>1e-4</bias_stddev>
                                </noise>
                            </y>
                            <z>
                                <noise type="gaussian">
                                    <mean>0.0</mean>
                                    <stddev>0.002</stddev>
                                    <bias_mean>0.0008</bias_mean>
                                    <bias_stddev>1e-4</bias_stddev>
                                </noise>
                            </z>
                        </angular_velocity>

                        <linear_acceleration>
                            <x>
                                <noise type="gaussian">
                                    <mean>0.0</mean>
                                    <stddev>0.05</stddev>           <!-- m/s^2 white noise -->
                                    <bias_mean>0.02</bias_mean>     <!-- m/s^2 bias -->
                                    <bias_stddev>0.005</bias_stddev><!-- m/s^2 bias RW -->
                                </noise>
                            </x>
                            <y>
                                <noise type="gaussian">
                                    <mean>0.0</mean>
                                    <stddev>0.05</stddev>
                                    <bias_mean>0.02</bias_mean>
                                    <bias_stddev>0.005</bias_stddev>
                                </noise>
                            </y>
                            <z>
                                <noise type="gaussian">
                                    <mean>0.0</mean>
                                    <stddev>0.05</stddev>
                                    <bias_mean>0.03</bias_mean>
                                    <bias_stddev>0.005</bias_stddev>
                                </noise>
                            </z>
                        </linear_acceleration>
                    </imu>
                </sensor>

                <!-- GPS on base_link -->
                <sensor name="gps_sensor" type="gps">
                    <always_on>true</always_on>
                    <update_rate>5</update_rate>
                    <visualize>false</visualize>
                    <pose>0 0 0.10 0 0 0</pose>
                    <topic>gps</topic>
                    <gps>
                        <position_sensing>
                            <horizontal>
                                <noise type="gaussian">
                                    <mean>0.0</mean>
                                    <stddev>0.1</stddev>  <!-- meters RMS -->
                                </noise>
                            </horizontal>
                            <vertical>
                                <noise type="gaussian">
                                    <mean>0.0</mean>
                                    <stddev>0.1</stddev>  <!-- meters RMS -->
                                </noise>
                            </vertical>
                        </position_sensing>
                        <velocity_sensing>
                            <noise type="gaussian">
                                <mean>0.0</mean>
                                <stddev>0.05</stddev>    <!-- m/s RMS -->
                            </noise>
                        </velocity_sensing>
                    </gps>
                </sensor>


                <pose relative_to='__model__'>0.5 0 0.4 0 0 0</pose>
                <inertial>
                    <mass>1.14395</mass>
                    <inertia>
                        <ixx>0.095329</ixx>
                        <ixy>0</ixy>
                        <ixz>0</ixz>
                        <iyy>0.381317</iyy>
                        <iyz>0</iyz>
                        <izz>0.476646</izz>
                    </inertia>
                </inertial>
                <visual name='visual'>
                    <geometry>
                        <box>
                            <size>2.0 1.0 0.5</size>
                        </box>
                    </geometry>
                    <material>
                        <ambient>0.1 0.1 0.1 1</ambient>
                        <diffuse>0.2 0.4 0.5 1</diffuse>
                        <specular>0.2 0.2 0.2 1</specular>
                    </material>
                </visual>
                <collision name='collision'>
                    <geometry>
                        <box>
                            <size>2.0 1.0 0.5</size>
                        </box>
                    </geometry>
                </collision>
            </link>
            <!-- Wheels -->
            <link name='left_wheel'>
                <pose relative_to="chassis">-0.5 0.6 0 -1.5707 0 0</pose>
                <inertial>
                    <mass>1</mass>
                    <inertia>
                        <ixx>0.043333</ixx>
                        <ixy>0</ixy>
                        <ixz>0</ixz>
                        <iyy>0.043333</iyy>
                        <iyz>0</iyz>
                        <izz>0.08</izz>
                    </inertia>
                </inertial>
                <visual name='visual'>
                    <geometry>
                        <cylinder>
                            <radius>0.4</radius>
                            <length>0.2</length>
                        </cylinder>
                    </geometry>
                    <material>
                        <ambient>0.0 0.0 0.0 1</ambient>
                        <diffuse>0.0 0.0 0.0 1</diffuse>
                        <specular>0.0 0.0 0.0 1</specular>
                    </material>
                </visual>
                <collision name='collision'>
                    <geometry>
                        <cylinder>
                            <radius>0.4</radius>
                            <length>0.2</length>
                        </cylinder>
                    </geometry>
                </collision>
            </link>
            <link name='right_wheel'>
                <pose relative_to="chassis">-0.5 -0.6 0 -1.5707 0 0</pose>
                <inertial>
                    <mass>1</mass>
                    <inertia>
                        <ixx>0.043333</ixx>
                        <ixy>0</ixy>
                        <ixz>0</ixz>
                        <iyy>0.043333</iyy>
                        <iyz>0</iyz>
                        <izz>0.08</izz>
                    </inertia>
                </inertial>
                <visual name='visual'>
                    <geometry>
                        <cylinder>
                            <radius>0.4</radius>
                            <length>0.2</length>
                        </cylinder>
                    </geometry>
                    <material>
                        <ambient>0.0 0.0 0.0 1</ambient>
                        <diffuse>0.0 0.0 0.0 1</diffuse>
                        <specular>0.0 0.0 0.0 1</specular>
                    </material>
                </visual>
                <collision name='collision'>
                    <geometry>
                        <cylinder>
                            <radius>0.4</radius>
                            <length>0.2</length>
                        </cylinder>
                    </geometry>
                </collision>
            </link>
            <!-- Caster wheel -->
            <link name='caster'>
                <pose relative_to='caster_frame' />
                <inertial>
                    <mass>1</mass>
                    <inertia>
                        <ixx>0.016</ixx>
                        <ixy>0</ixy>
                        <ixz>0</ixz>
                        <iyy>0.016</iyy>
                        <iyz>0</iyz>
                        <izz>0.016</izz>
                    </inertia>
                </inertial>
                <visual name='visual'>
                    <geometry>
                        <sphere>
                            <radius>0.2</radius>
                        </sphere>
                    </geometry>
                    <material>
                        <ambient>0.2 0.2 0.2 1</ambient>
                        <diffuse>0.5 0.5 0.5 1</diffuse>
                        <specular>1 1 1 1</specular>
                    </material>
                </visual>
                <collision name='collision'>
                    <geometry>
                        <sphere>
                            <radius>0.2</radius>
                        </sphere>
                    </geometry>
                </collision>
            </link>

            <!-- Joints -->
            <joint name='left_wheel_joint' type='revolute'>
                <pose relative_to='left_wheel' />
                <parent>chassis</parent>
                <child>left_wheel</child>
                <axis>
                    <xyz expressed_in='__model__'>0 1 0</xyz>
                    <limit>
                        <lower>-1.79769e+308</lower>
                        <upper>1.79769e+308</upper>
                    </limit>
                </axis>
            </joint>

            <joint name='right_wheel_joint' type='revolute'>
                <pose relative_to='right_wheel' />
                <parent>chassis</parent>
                <child>right_wheel</child>
                <axis>
                    <xyz expressed_in='__model__'>0 1 0</xyz>
                    <limit>
                        <lower>-1.79769e+308</lower>
                        <upper>1.79769e+308</upper>
                    </limit>
                </axis>
            </joint>

            <joint name='caster_wheel' type='ball'>
                <parent>chassis</parent>
                <child>caster</child>
            </joint>
        </model>

    </world>
</sdf>